<?xml version="1.0"?>
<robot name="robot_name" xmlns:xacro="http://www.ros.org/wiki/xacro">
    <xacro:include filename = "camera_xacro.urdf"/>
    <!-- Definición de propiedades -->
    <xacro:property name="lado_caja_base" value="0.2"/>
    <xacro:property name="alto_caja_base" value="0.1"/>
    <xacro:property name="masa_caja_base" value="50"/>

    <xacro:property name="radio_cilindro" value="0.1"/>
    <xacro:property name="alto_cilindro" value="0.05"/>
    <xacro:property name="masa_cilindro" value="0.01"/>

    <xacro:property name="lado_caja_brazo" value="0.07"/>
    <xacro:property name="alto_caja_brazo" value="0.4"/>
    <xacro:property name="masa_caja_brazo" value="0.01"/>

    <xacro:property name="lado_caja_antebrazo" value="0.05"/>
    <xacro:property name="alto_caja_antebrazo" value="0.4"/>
    <xacro:property name="masa_caja_antebrazo" value="0.01"/>

    <xacro:property name="color_yellow" value="0.7 0.7 0.1 1.0"/>
    <xacro:property name="color_red" value="0.7 0.1 0.1 1.0"/>
    <xacro:property name="color_blue" value="0.1 0.1 0.7 1.0"/>
    <xacro:property name="color_green" value="0.1 0.7 0.1 1.0"/>

    <!-- Macros de inercia -->
    <xacro:macro name="inercia_caja" params = "m w h d">
        <inertial>
            <origin xyz="0.0 0.0 0.0" rpy="${pi/2} 0.0 ${pi/2}"/>
            <mass value="${m}"/>
            <inertia ixx="${(m/12) * (h*h + d*d)}" ixy="0.0" ixz="0.0" iyy="${(m/12) * (w*w + d*d)}" iyz="0.0" izz="${(m/12) * (h*h + w*w)}"/>
        </inertial>
    </xacro:macro>

    <xacro:macro name="inercia_cilindro" params = "m r h">
        <inertial>
            <origin xyz="0.0 0.0 0.0" rpy="${pi/2} 0.0 0.0"/>
            <mass value="${m}"/>
            <inertia ixx="${(m/12) * (3*r*r + h*h)}" ixy="0.0" ixz="0.0" iyy="${(m/12) * (3*r*r + h*h)}" iyz="0.0" izz="${(m/2) * (r*r)}"/>
        </inertial>
    </xacro:macro>

    <!-- Base link -->
    <link name="base_link">
        <visual>
            <origin xyz="0.0 0.0 ${alto_caja_base/2}" rpy="0.0 0.0 0.0"/>
            <geometry>
                <box size="${lado_caja_base} ${lado_caja_base} ${alto_caja_base}"/>
            </geometry>
            <material name="yellow">
                <color rgba="${color_yellow}"/>
            </material>
        </visual>
        <collision>
            <origin xyz="0.0 0.0 ${alto_caja_base/2}" rpy="0.0 0.0 0.0"/>
            <geometry>
                <box size="${lado_caja_base} ${lado_caja_base} ${alto_caja_base}"/>
            </geometry>
        </collision>
        <xacro:inercia_caja m="${masa_caja_base}" w="${lado_caja_base}" d="${lado_caja_base}" h="${alto_caja_base}"/>
    </link>

    <gazebo reference="base_link">
        <material>Gazebo/Orange</material>
    </gazebo>

    <!-- Base giratoria -->
    <link name="base_giratoria">
        <visual>
            <origin xyz="0.0 0.0 ${alto_cilindro/2}" rpy="0.0 0.0 0.0"/>
            <geometry>
                <cylinder radius="${radio_cilindro}" length="${alto_cilindro}"/>
            </geometry>
            <material name="red">
                <color rgba="${color_red}"/>
            </material>
        </visual>
        <collision>
            <origin xyz="0.0 0.0 ${alto_cilindro/2}" rpy="0.0 0.0 0.0"/>
            <geometry>
                <cylinder radius="${radio_cilindro}" length="${alto_cilindro}"/>
            </geometry>
        </collision>
        <xacro:inercia_cilindro m="${masa_cilindro}" r="${radio_cilindro}" h="${alto_cilindro}"/>
    </link>

    <gazebo reference="base_giratoria">
        <material>Gazebo/Orange</material>
    </gazebo>

    <!-- Brazo -->
    <link name="brazo">
        <visual>
            <origin xyz="0.0 ${lado_caja_brazo/2} ${alto_caja_brazo/2}" rpy="0.0 0.0 0.0"/>
            <geometry>
                <box size="${lado_caja_brazo} ${lado_caja_brazo} ${alto_caja_brazo}"/>
            </geometry>
            <material name="blue">
                <color rgba="${color_blue}"/>
            </material>
        </visual>
        <collision>
            <origin xyz="0.0 ${lado_caja_brazo/2} ${alto_caja_brazo/2}" rpy="0.0 0.0 0.0"/>
            <geometry>
                <box size="${lado_caja_brazo} ${lado_caja_brazo} ${alto_caja_brazo}"/>
            </geometry>
        </collision>
        <xacro:inercia_caja m="${masa_caja_brazo}" w="${lado_caja_brazo}" d="${lado_caja_brazo}" h="${alto_caja_brazo}"/>
    </link>

    <gazebo reference="brazo">
        <material>Gazebo/Orange</material>
    </gazebo>

    <!-- Antebrazo -->
    <link name="antebrazo">
        <visual>
            <origin xyz="0.0 ${lado_caja_antebrazo/2} ${alto_caja_antebrazo/2}" rpy="0.0 0.0 0.0"/>
            <geometry>
                <box size="${lado_caja_antebrazo} ${lado_caja_antebrazo} ${alto_caja_antebrazo}"/>
            </geometry>
            <material name="green">
                <color rgba="${color_green}"/>
            </material>
        </visual>
        <collision>
            <origin xyz="0.0 ${lado_caja_antebrazo/2} ${alto_caja_antebrazo/2}" rpy="0.0 0.0 0.0"/>
            <geometry>
                <box size="${lado_caja_antebrazo} ${lado_caja_antebrazo} ${alto_caja_antebrazo}"/>
            </geometry>
        </collision>
        <xacro:inercia_caja m="${masa_caja_antebrazo}" w="${lado_caja_antebrazo}" d="${lado_caja_antebrazo}" h="${alto_caja_antebrazo}"/>
    </link>

    <gazebo reference="antebrazo">
        <material>Gazebo/Orange</material>
    </gazebo>


    <!-- Joints -->
    <joint name="base_giro_joint" type="revolute">
        <parent link="base_link"/>
        <child link="base_giratoria"/>
        <axis xyz="0.0 0.0 1.0"/>
        <origin xyz="0.0 0.0 ${alto_caja_base}" rpy="0.0 0.0 0.0"/>
        <limit lower="${-pi/2}" upper="${pi/2}" effort="100" velocity="100"/>
    </joint>

    <joint name="base_brazo_joint" type="revolute">
        <parent link="base_giratoria"/>
        <child link="brazo"/>
        <origin xyz="0.0 ${-lado_caja_brazo/2} ${alto_cilindro}" rpy="0.0 0.0 0.0"/>
        <limit lower="0" upper="${pi/2}" effort="100" velocity="100"/>
    </joint>

    <joint name="antebrazo_brazo_joint" type="revolute">
        <parent link="brazo"/>
        <child link="antebrazo"/>
        <origin xyz="0.0 0.0 ${alto_caja_brazo}" rpy="0.0 0.0 0.0"/>
        <limit lower="0" upper="${pi}" effort="100" velocity="100"/>
    </joint>

</robot>
