<?xml version="1.0" ?>
<!-- =================================================================================== -->
<!-- |    This document was autogenerated by xacro from proyecto_xacro.urdf            | -->
<!-- |    EDITING THIS FILE BY HAND IS NOT RECOMMENDED                                 | -->
<!-- =================================================================================== -->
<robot name="robot_name">
  <!-- Base link -->
  <link name="base_link">
    <visual>
      <origin rpy="0.0 0.0 0.0" xyz="0.0 0.0 0.05"/>
      <geometry>
        <box size="0.2 0.2 0.1"/>
      </geometry>
      <material name="yellow">
        <color rgba="0.7 0.7 0.1 1.0"/>
      </material>
    </visual>
    <collision>
      <origin rpy="0.0 0.0 0.0" xyz="0.0 0.0 0.05"/>
      <geometry>
        <box size="0.2 0.2 0.1"/>
      </geometry>
    </collision>
    <inertial>
      <origin rpy="1.5707963267948966 0.0 1.5707963267948966" xyz="0.0 0.0 0.0"/>
      <mass value="50"/>
      <inertia ixx="0.2083333333333334" ixy="0.0" ixz="0.0" iyy="0.3333333333333334" iyz="0.0" izz="0.2083333333333334"/>
    </inertial>
  </link>
  <gazebo reference="base_link">
    <material>Gazebo/Orange</material>
  </gazebo>
  <!-- Base giratoria -->
  <link name="base_giratoria">
    <visual>
      <origin rpy="0.0 0.0 0.0" xyz="0.0 0.0 0.025"/>
      <geometry>
        <cylinder length="0.05" radius="0.1"/>
      </geometry>
      <material name="red">
        <color rgba="0.7 0.1 0.1 1.0"/>
      </material>
    </visual>
    <collision>
      <origin rpy="0.0 0.0 0.0" xyz="0.0 0.0 0.025"/>
      <geometry>
        <cylinder length="0.05" radius="0.1"/>
      </geometry>
    </collision>
    <inertial>
      <origin rpy="1.5707963267948966 0.0 0.0" xyz="0.0 0.0 0.0"/>
      <mass value="0.01"/>
      <inertia ixx="2.7083333333333342e-05" ixy="0.0" ixz="0.0" iyy="2.7083333333333342e-05" iyz="0.0" izz="5.000000000000001e-05"/>
    </inertial>
  </link>
  <gazebo reference="base_giratoria">
    <material>Gazebo/Orange</material>
  </gazebo>
  <!-- Brazo -->
  <link name="brazo">
    <visual>
      <origin rpy="0.0 0.0 0.0" xyz="0.0 0.035 0.2"/>
      <geometry>
        <box size="0.07 0.07 0.4"/>
      </geometry>
      <material name="blue">
        <color rgba="0.1 0.1 0.7 1.0"/>
      </material>
    </visual>
    <collision>
      <origin rpy="0.0 0.0 0.0" xyz="0.0 0.035 0.2"/>
      <geometry>
        <box size="0.07 0.07 0.4"/>
      </geometry>
    </collision>
    <inertial>
      <origin rpy="1.5707963267948966 0.0 1.5707963267948966" xyz="0.0 0.0 0.0"/>
      <mass value="0.01"/>
      <inertia ixx="0.00013741666666666668" ixy="0.0" ixz="0.0" iyy="8.166666666666668e-06" iyz="0.0" izz="0.00013741666666666668"/>
    </inertial>
  </link>
  <gazebo reference="brazo">
    <material>Gazebo/Orange</material>
  </gazebo>
  <!-- Antebrazo -->
  <link name="antebrazo">
    <visual>
      <origin rpy="0.0 0.0 0.0" xyz="0.0 0.025 0.2"/>
      <geometry>
        <box size="0.05 0.05 0.4"/>
      </geometry>
      <material name="green">
        <color rgba="0.1 0.7 0.1 1.0"/>
      </material>
    </visual>
    <collision>
      <origin rpy="0.0 0.0 0.0" xyz="0.0 0.025 0.2"/>
      <geometry>
        <box size="0.05 0.05 0.4"/>
      </geometry>
    </collision>
    <inertial>
      <origin rpy="1.5707963267948966 0.0 1.5707963267948966" xyz="0.0 0.0 0.0"/>
      <mass value="0.01"/>
      <inertia ixx="0.00013541666666666671" ixy="0.0" ixz="0.0" iyy="4.166666666666668e-06" iyz="0.0" izz="0.00013541666666666671"/>
    </inertial>
  </link>
  <gazebo reference="antebrazo">
    <material>Gazebo/Orange</material>
  </gazebo>
  <!-- Joints -->
  <joint name="base_giro_joint" type="revolute">
    <parent link="base_link"/>
    <child link="base_giratoria"/>
    <axis xyz="0.0 0.0 1.0"/>
    <origin rpy="0.0 0.0 0.0" xyz="0.0 0.0 0.1"/>
    <limit effort="100" lower="-1.5707963267948966" upper="1.5707963267948966" velocity="100"/>
  </joint>
  <joint name="base_brazo_joint" type="revolute">
    <parent link="base_giratoria"/>
    <child link="brazo"/>
    <origin rpy="0.0 0.0 0.0" xyz="0.0 -0.035 0.05"/>
    <limit effort="100" lower="0" upper="1.5707963267948966" velocity="100"/>
  </joint>
  <joint name="antebrazo_brazo_joint" type="revolute">
    <parent link="brazo"/>
    <child link="antebrazo"/>
    <origin rpy="0.0 0.0 0.0" xyz="0.0 0.0 0.4"/>
    <limit effort="100" lower="0" upper="3.141592653589793" velocity="100"/>
  </joint>
</robot>
